Workbook

Sheet Start
B2: Debt Payoff Calculator (free)
B3: Enter your debts, set one monthly budget, and see the month you become debt-free.
B5: DEBT-FREE BY | E5: MONTHS TO GO | G5: TOTAL INTEREST
B6: =IF(Calc!$B$4=0,"Enter your debts below",IF(Calc!$C$4>$D$9,"Budget must be at least $"&TEXT(Calc!$C$4,"#,##0"),IF(IF($D$10="Avalanche",Calc!$B$3,Calc!$B$2)>120,"Over 10 years — raise your monthly budget by $"&TEXT(Calc!$D$4,"#,##0"),TEXT(EDATE($D$11,IF($D$10="Avalanche",Calc!$B$3,Calc!$B$2)-1),"mmm yyyy")))) | E6: =IF(Calc!$B$4=0,"-",IF(IF($D$10="Avalanche",Calc!$B$3,Calc!$B$2)>120,"120+",IF($D$10="Avalanche",Calc!$B$3,Calc!$B$2))) | G6: =IF(Calc!$B$4=0,"-",IF(IF($D$10="Avalanche",Calc!$B$3,Calc!$B$2)>120,"-",IF($D$10="Avalanche",Calc!$C$3,Calc!$C$2)))
B7: =IF(Calc!$B$4=0,"Tip: start with the debt you feel worst about — it usually is the smallest one.",IF(Calc!$C$4>$D$9,"Your minimum payments add up to more than your budget. Raise the budget or check the amounts.","Paying $"&TEXT($H$11,"#,##0")&" extra every month with the "&$D$10&" method ("&IF($D$10="Avalanche","highest APR first","smallest balance first")&")."))
B9: Monthly budget | F9: Total balance | H9: =SUM(D14:D28)
B10: Payoff method | D10: Snowball | F10: Minimum payments | H10: =Calc!C4
B11: First payment month | D11: =DATE(YEAR(TODAY()),MONTH(TODAY())+1,1) | F11: Extra toward debt | H11: =MAX(0,D9-H10)
B13: # | C13: Debt name | D13: Balance | E13: APR % | F13: Minimum payment | G13: Order | H13: Paid off
B14: 1 | G14: =IF($D$10="Avalanche",Calc!F6,Calc!D6) | H14: =IF(G14="","",IF(IF($D$10="Avalanche",Calc!H6,Calc!G6)>120,"120+ months",TEXT(EDATE($D$11,IF($D$10="Avalanche",Calc!H6,Calc!G6)-1),"mmm yyyy")))
B15: 2 | G15: =IF($D$10="Avalanche",Calc!F7,Calc!D7) | H15: =IF(G15="","",IF(IF($D$10="Avalanche",Calc!H7,Calc!G7)>120,"120+ months",TEXT(EDATE($D$11,IF($D$10="Avalanche",Calc!H7,Calc!G7)-1),"mmm yyyy")))
B16: 3 | G16: =IF($D$10="Avalanche",Calc!F8,Calc!D8) | H16: =IF(G16="","",IF(IF($D$10="Avalanche",Calc!H8,Calc!G8)>120,"120+ months",TEXT(EDATE($D$11,IF($D$10="Avalanche",Calc!H8,Calc!G8)-1),"mmm yyyy")))
B17: 4 | G17: =IF($D$10="Avalanche",Calc!F9,Calc!D9) | H17: =IF(G17="","",IF(IF($D$10="Avalanche",Calc!H9,Calc!G9)>120,"120+ months",TEXT(EDATE($D$11,IF($D$10="Avalanche",Calc!H9,Calc!G9)-1),"mmm yyyy")))
B18: 5 | G18: =IF($D$10="Avalanche",Calc!F10,Calc!D10) | H18: =IF(G18="","",IF(IF($D$10="Avalanche",Calc!H10,Calc!G10)>120,"120+ months",TEXT(EDATE($D$11,IF($D$10="Avalanche",Calc!H10,Calc!G10)-1),"mmm yyyy")))
B19: 6 | G19: =IF($D$10="Avalanche",Calc!F11,Calc!D11) | H19: =IF(G19="","",IF(IF($D$10="Avalanche",Calc!H11,Calc!G11)>120,"120+ months",TEXT(EDATE($D$11,IF($D$10="Avalanche",Calc!H11,Calc!G11)-1),"mmm yyyy")))
B20: 7 | G20: =IF($D$10="Avalanche",Calc!F12,Calc!D12) | H20: =IF(G20="","",IF(IF($D$10="Avalanche",Calc!H12,Calc!G12)>120,"120+ months",TEXT(EDATE($D$11,IF($D$10="Avalanche",Calc!H12,Calc!G12)-1),"mmm yyyy")))
B21: 8 | G21: =IF($D$10="Avalanche",Calc!F13,Calc!D13) | H21: =IF(G21="","",IF(IF($D$10="Avalanche",Calc!H13,Calc!G13)>120,"120+ months",TEXT(EDATE($D$11,IF($D$10="Avalanche",Calc!H13,Calc!G13)-1),"mmm yyyy")))
B22: 9 | G22: =IF($D$10="Avalanche",Calc!F14,Calc!D14) | H22: =IF(G22="","",IF(IF($D$10="Avalanche",Calc!H14,Calc!G14)>120,"120+ months",TEXT(EDATE($D$11,IF($D$10="Avalanche",Calc!H14,Calc!G14)-1),"mmm yyyy")))
B23: 10 | G23: =IF($D$10="Avalanche",Calc!F15,Calc!D15) | H23: =IF(G23="","",IF(IF($D$10="Avalanche",Calc!H15,Calc!G15)>120,"120+ months",TEXT(EDATE($D$11,IF($D$10="Avalanche",Calc!H15,Calc!G15)-1),"mmm yyyy")))
B24: 11 | G24: =IF($D$10="Avalanche",Calc!F16,Calc!D16) | H24: =IF(G24="","",IF(IF($D$10="Avalanche",Calc!H16,Calc!G16)>120,"120+ months",TEXT(EDATE($D$11,IF($D$10="Avalanche",Calc!H16,Calc!G16)-1),"mmm yyyy")))
B25: 12 | G25: =IF($D$10="Avalanche",Calc!F17,Calc!D17) | H25: =IF(G25="","",IF(IF($D$10="Avalanche",Calc!H17,Calc!G17)>120,"120+ months",TEXT(EDATE($D$11,IF($D$10="Avalanche",Calc!H17,Calc!G17)-1),"mmm yyyy")))
... B28: 15 | G28: =IF($D$10="Avalanche",Calc!F20,Calc!D20) | H28: =IF(G28="","",IF(IF($D$10="Avalanche",Calc!H20,Calc!G20)>120,"120+ months",TEXT(EDATE($D$11,IF($D$10="Avalanche",Calc!H20,Calc!G20)-1),"mmm yyyy")))
B30: Type only in the light-yellow cells. Everything else is calculated. APR: type 19.99 for 19.99%.
B31: See what to pay on each debt every month in the Schedule tab. Want to know each month if you're ahead or behind? See 'Track your progress'.

Sheet Schedule
B2: Payment schedule
B3: What to pay on each debt every month with your budget and method (from the Start tab). Balances are at the end of each month.
B5: Month # | C5: Month | D5: Total paid | E5: Interest | F5: Total balance | G5: =IF(Calc!$B$6=0,"",IF(Start!$C$14="","Debt 1",Start!$C$14)) | I5: =IF(Calc!$B$7=0,"",IF(Start!$C$15="","Debt 2",Start!$C$15)) | K5: =IF(Calc!$B$8=0,"",IF(Start!$C$16="","Debt 3",Start!$C$16)) | M5: =IF(Calc!$B$9=0,"",IF(Start!$C$17="","Debt 4",Start!$C$17)) | O5: =IF(Calc!$B$10=0,"",IF(Start!$C$18="","Debt 5",Start!$C$18)) | Q5: =IF(Calc!$B$11=0,"",IF(Start!$C$19="","Debt 6",Start!$C$19)) | S5: =IF(Calc!$B$12=0,"",IF(Start!$C$20="","Debt 7",Start!$C$20)) | U5: =IF(Calc!$B$13=0,"",IF(Start!$C$21="","Debt 8",Start!$C$21)) | W5: =IF(Calc!$B$14=0,"",IF(Start!$C$22="","Debt 9",Start!$C$22)) | Y5: =IF(Calc!$B$15=0,"",IF(Start!$C$23="","Debt 10",Start!$C$23)) | AA5: =IF(Calc!$B$16=0,"",IF(Start!$C$24="","Debt 11",Start!$C$24)) | AC5: =IF(Calc!$B$17=0,"",IF(Start!$C$25="","Debt 12",Start!$C$25)) | AE5: =IF(Calc!$B$18=0,"",IF(Start!$C$26="","Debt 13",Start!$C$26)) | AG5: =IF(Calc!$B$19=0,"",IF(Start!$C$27="","Debt 14",Start!$C$27)) | AI5: =IF(Calc!$B$20=0,"",IF(Start!$C$28="","Debt 15",Start!$C$28))
G6: Payment | H6: Balance | I6: Payment | J6: Balance | K6: Payment | L6: Balance | M6: Payment | N6: Balance | O6: Payment | P6: Balance | Q6: Payment | R6: Balance | S6: Payment | T6: Balance | U6: Payment | V6: Balance | W6: Payment | X6: Balance | Y6: Payment | Z6: Balance | AA6: Payment | AB6: Balance | AC6: Payment | AD6: Balance | AE6: Payment | AF6: Balance | AG6: Payment | AH6: Balance | AI6: Payment | AJ6: Balance
B7: 1 | C7: =IF(Calc!$B$4=0,"",EDATE(Start!$D$11,0)) | D7: =IF(OR(Calc!$B$4=0,$B7>IF(Start!$D$10="Avalanche",Calc!$B$3,Calc!$B$2)),"",SUM(G7,I7,K7,M7,O7,Q7,S7,U7,W7,Y7,AA7,AC7,AE7,AG7,AI7)) | E7: =IF(OR(Calc!$B$4=0,$B7>IF(Start!$D$10="Avalanche",Calc!$B$3,Calc!$B$2)),"",IF(Start!$D$10="Avalanche",Calc!C$72,Calc!C$47)) | F7: =IF(Calc!$B$4=0,"",IF($B7>IF(Start!$D$10="Avalanche",Calc!$B$3,Calc!$B$2),NA(),SUM(H7,J7,L7,N7,P7,R7,T7,V7,X7,Z7,AB7,AD7,AF7,AH7,AJ7))) | G7: =IF(H7="","",Start!$D$14*(1+Start!$E$14/12)-H7) | H7: =IF(OR(OR(Calc!$B$4=0,$B7>IF(Start!$D$10="Avalanche",Calc!$B$3,Calc!$B$2)),Calc!$B$6=0),"",IF(Start!$D$14<=0.005,"",IF(Start!$D$10="Avalanche",INDEX(Calc!E$75:E$89,Calc!$F$6),INDEX(Calc!E$50:E$64,Calc!$D$6)))) | I7: =IF(J7="","",Start!$D$15*(1+Start!$E$15/12)-J7) | J7: =IF(OR(OR(Calc!$B$4=0,$B7>IF(Start!$D$10="Avalanche",Calc!$B$3,Calc!$B$2)),Calc!$B$7=0),"",IF(Start!$D$15<=0.005,"",IF(Start!$D$10="Avalanche",INDEX(Calc!E$75:E$89,Calc!$F$7),INDEX(Calc!E$50:E$64,Calc!$D$7)))) | K7: =IF(L7="","",Start!$D$16*(1+Start!$E$16/12)-L7) | L7: =IF(OR(OR(Calc!$B$4=0,$B7>IF(Start!$D$10="Avalanche",Calc!$B$3,Calc!$B$2)),Calc!$B$8=0),"",IF(Start!$D$16<=0.005,"",IF(Start!$D$10="Avalanche",INDEX(Calc!E$75:E$89,Calc!$F$8),INDEX(Calc!E$50:E$64,Calc!$D$8)))) | M7: =IF(N7="","",Start!$D$17*(1+Start!$E$17/12)-N7) | N7: =IF(OR(OR(Calc!$B$4=0,$B7>IF(Start!$D$10="Avalanche",Calc!$B$3,Calc!$B$2)),Calc!$B$9=0),"",IF(Start!$D$17<=0.005,"",IF(Start!$D$10="Avalanche",INDEX(Calc!E$75:E$89,Calc!$F$9),INDEX(Calc!E$50:E$64,Calc!$D$9)))) | O7: =IF(P7="","",Start!$D$18*(1+Start!$E$18/12)-P7) | P7: =IF(OR(OR(Calc!$B$4=0,$B7>IF(Start!$D$10="Avalanche",Calc!$B$3,Calc!$B$2)),Calc!$B$10=0),"",IF(Start!$D$18<=0.005,"",IF(Start!$D$10="Avalanche",INDEX(Calc!E$75:E$89,Calc!$F$10),INDEX(Calc!E$50:E$64,Calc!$D$10)))) | Q7: =IF(R7="","",Start!$D$19*(1+Start!$E$19/12)-R7) | R7: =IF(OR(OR(Calc!$B$4=0,$B7>IF(Start!$D$10="Avalanche",Calc!$B$3,Calc!$B$2)),Calc!$B$11=0),"",IF(Start!$D$19<=0.005,"",IF(Start!$D$10="Avalanche",INDEX(Calc!E$75:E$89,Calc!$F$11),INDEX(Calc!E$50:E$64,Calc!$D$11)))) | S7: =IF(T7="","",Start!$D$20*(1+Start!$E$20/12)-T7) | T7: =IF(OR(OR(Calc!$B$4=0,$B7>IF(Start!$D$10="Avalanche",Calc!$B$3,Calc!$B$2)),Calc!$B$12=0),"",IF(Start!$D$20<=0.005,"",IF(Start!$D$10="Avalanche",INDEX(Calc!E$75:E$89,Calc!$F$12),INDEX(Calc!E$50:E$64,Calc!$D$12)))) | U7: =IF(V7="","",Start!$D$21*(1+Start!$E$21/12)-V7) | V7: =IF(OR(OR(Calc!$B$4=0,$B7>IF(Start!$D$10="Avalanche",Calc!$B$3,Calc!$B$2)),Calc!$B$13=0),"",IF(Start!$D$21<=0.005,"",IF(Start!$D$10="Avalanche",INDEX(Calc!E$75:E$89,Calc!$F$13),INDEX(Calc!E$50:E$64,Calc!$D$13)))) | W7: =IF(X7="","",Start!$D$22*(1+Start!$E$22/12)-X7) | X7: =IF(OR(OR(Calc!$B$4=0,$B7>IF(Start!$D$10="Avalanche",Calc!$B$3,Calc!$B$2)),Calc!$B$14=0),"",IF(Start!$D$22<=0.005,"",IF(Start!$D$10="Avalanche",INDEX(Calc!E$75:E$89,Calc!$F$14),INDEX(Calc!E$50:E$64,Calc!$D$14)))) | Y7: =IF(Z7="","",Start!$D$23*(1+Start!$E$23/12)-Z7) | Z7: =IF(OR(OR(Calc!$B$4=0,$B7>IF(Start!$D$10="Avalanche",Calc!$B$3,Calc!$B$2)),Calc!$B$15=0),"",IF(Start!$D$23<=0.005,"",IF(Start!$D$10="Avalanche",INDEX(Calc!E$75:E$89,Calc!$F$15),INDEX(Calc!E$50:E$64,Calc!$D$15)))) | AA7: =IF(AB7="","",Start!$D$24*(1+Start!$E$24/12)-AB7) | AB7: =IF(OR(OR(Calc!$B$4=0,$B7>IF(Start!$D$10="Avalanche",Calc!$B$3,Calc!$B$2)),Calc!$B$16=0),"",IF(Start!$D$24<=0.005,"",IF(Start!$D$10="Avalanche",INDEX(Calc!E$75:E$89,Calc!$F$16),INDEX(Calc!E$50:E$64,Calc!$D$16)))) | AC7: =IF(AD7="","",Start!$D$25*(1+Start!$E$25/12)-AD7) | AD7: =IF(OR(OR(Calc!$B$4=0,$B7>IF(Start!$D$10="Avalanche",Calc!$B$3,Calc!$B$2)),Calc!$B$17=0),"",IF(Start!$D$25<=0.005,"",IF(Start!$D$10="Avalanche",INDEX(Calc!E$75:E$89,Calc!$F$17),INDEX(Calc!E$50:E$64,Calc!$D$17)))) | AE7: =IF(AF7="","",Start!$D$26*(1+Start!$E$26/12)-AF7) | AF7: =IF(OR(OR(Calc!$B$4=0,$B7>IF(Start!$D$10="Avalanche",Calc!$B$3,Calc!$B$2)),Calc!$B$18=0),"",IF(Start!$D$26<=0.005,"",IF(Start!$D$10="Avalanche",INDEX(Calc!E$75:E$89,Calc!$F$18),INDEX(Calc!E$50:E$64,Calc!$D$18)))) | AG7: =IF(AH7="","",Start!$D$27*(1+Start!$E$27/12)-AH7) | AH7: =IF(OR(OR(Calc!$B$4=0,$B7>IF(Start!$D$10="Avalanche",Calc!$B$3,Calc!$B$2)),Calc!$B$19=0),"",IF(Start!$D$27<=0.005,"",IF(Start!$D$10="Avalanche",INDEX(Calc!E$75:E$89,Calc!$F$19),INDEX(Calc!E$50:E$64,Calc!$D$19)))) | AI7: =IF(AJ7="","",Start!$D$28*(1+Start!$E$28/12)-AJ7) | AJ7: =IF(OR(OR(Calc!$B$4=0,$B7>IF(Start!$D$10="Avalanche",Calc!$B$3,Calc!$B$2)),Calc!$B$20=0),"",IF(Start!$D$28<=0.005,"",IF(Start!$D$10="Avalanche",INDEX(Calc!E$75:E$89,Calc!$F$20),INDEX(Calc!E$50:E$64,Calc!$D$20))))
B8: 2 | C8: =IF(Calc!$B$4=0,"",EDATE(Start!$D$11,1)) | D8: =IF(OR(Calc!$B$4=0,$B8>IF(Start!$D$10="Avalanche",Calc!$B$3,Calc!$B$2)),"",SUM(G8,I8,K8,M8,O8,Q8,S8,U8,W8,Y8,AA8,AC8,AE8,AG8,AI8)) | E8: =IF(OR(Calc!$B$4=0,$B8>IF(Start!$D$10="Avalanche",Calc!$B$3,Calc!$B$2)),"",IF(Start!$D$10="Avalanche",Calc!F$72,Calc!F$47)) | F8: =IF(Calc!$B$4=0,"",IF($B8>IF(Start!$D$10="Avalanche",Calc!$B$3,Calc!$B$2),NA(),SUM(H8,J8,L8,N8,P8,R8,T8,V8,X8,Z8,AB8,AD8,AF8,AH8,AJ8))) | G8: =IF(H8="","",N(H7)*(1+Start!$E$14/12)-H8) | H8: =IF(OR(OR(Calc!$B$4=0,$B8>IF(Start!$D$10="Avalanche",Calc!$B$3,Calc!$B$2)),Calc!$B$6=0),"",IF(N(H7)<=0.005,"",IF(Start!$D$10="Avalanche",INDEX(Calc!H$75:H$89,Calc!$F$6),INDEX(Calc!H$50:H$64,Calc!$D$6)))) | I8: =IF(J8="","",N(J7)*(1+Start!$E$15/12)-J8) | J8: =IF(OR(OR(Calc!$B$4=0,$B8>IF(Start!$D$10="Avalanche",Calc!$B$3,Calc!$B$2)),Calc!$B$7=0),"",IF(N(J7)<=0.005,"",IF(Start!$D$10="Avalanche",INDEX(Calc!H$75:H$89,Calc!$F$7),INDEX(Calc!H$50:H$64,Calc!$D$7)))) | K8: =IF(L8="","",N(L7)*(1+Start!$E$16/12)-L8) | L8: =IF(OR(OR(Calc!$B$4=0,$B8>IF(Start!$D$10="Avalanche",Calc!$B$3,Calc!$B$2)),Calc!$B$8=0),"",IF(N(L7)<=0.005,"",IF(Start!$D$10="Avalanche",INDEX(Calc!H$75:H$89,Calc!$F$8),INDEX(Calc!H$50:H$64,Calc!$D$8)))) | M8: =IF(N8="","",N(N7)*(1+Start!$E$17/12)-N8) | N8: =IF(OR(OR(Calc!$B$4=0,$B8>IF(Start!$D$10="Avalanche",Calc!$B$3,Calc!$B$2)),Calc!$B$9=0),"",IF(N(N7)<=0.005,"",IF(Start!$D$10="Avalanche",INDEX(Calc!H$75:H$89,Calc!$F$9),INDEX(Calc!H$50:H$64,Calc!$D$9)))) | O8: =IF(P8="","",N(P7)*(1+Start!$E$18/12)-P8) | P8: =IF(OR(OR(Calc!$B$4=0,$B8>IF(Start!$D$10="Avalanche",Calc!$B$3,Calc!$B$2)),Calc!$B$10=0),"",IF(N(P7)<=0.005,"",IF(Start!$D$10="Avalanche",INDEX(Calc!H$75:H$89,Calc!$F$10),INDEX(Calc!H$50:H$64,Calc!$D$10)))) | Q8: =IF(R8="","",N(R7)*(1+Start!$E$19/12)-R8) | R8: =IF(OR(OR(Calc!$B$4=0,$B8>IF(Start!$D$10="Avalanche",Calc!$B$3,Calc!$B$2)),Calc!$B$11=0),"",IF(N(R7)<=0.005,"",IF(Start!$D$10="Avalanche",INDEX(Calc!H$75:H$89,Calc!$F$11),INDEX(Calc!H$50:H$64,Calc!$D$11)))) | S8: =IF(T8="","",N(T7)*(1+Start!$E$20/12)-T8) | T8: =IF(OR(OR(Calc!$B$4=0,$B8>IF(Start!$D$10="Avalanche",Calc!$B$3,Calc!$B$2)),Calc!$B$12=0),"",IF(N(T7)<=0.005,"",IF(Start!$D$10="Avalanche",INDEX(Calc!H$75:H$89,Calc!$F$12),INDEX(Calc!H$50:H$64,Calc!$D$12)))) | U8: =IF(V8="","",N(V7)*(1+Start!$E$21/12)-V8) | V8: =IF(OR(OR(Calc!$B$4=0,$B8>IF(Start!$D$10="Avalanche",Calc!$B$3,Calc!$B$2)),Calc!$B$13=0),"",IF(N(V7)<=0.005,"",IF(Start!$D$10="Avalanche",INDEX(Calc!H$75:H$89,Calc!$F$13),INDEX(Calc!H$50:H$64,Calc!$D$13)))) | W8: =IF(X8="","",N(X7)*(1+Start!$E$22/12)-X8) | X8: =IF(OR(OR(Calc!$B$4=0,$B8>IF(Start!$D$10="Avalanche",Calc!$B$3,Calc!$B$2)),Calc!$B$14=0),"",IF(N(X7)<=0.005,"",IF(Start!$D$10="Avalanche",INDEX(Calc!H$75:H$89,Calc!$F$14),INDEX(Calc!H$50:H$64,Calc!$D$14)))) | Y8: =IF(Z8="","",N(Z7)*(1+Start!$E$23/12)-Z8) | Z8: =IF(OR(OR(Calc!$B$4=0,$B8>IF(Start!$D$10="Avalanche",Calc!$B$3,Calc!$B$2)),Calc!$B$15=0),"",IF(N(Z7)<=0.005,"",IF(Start!$D$10="Avalanche",INDEX(Calc!H$75:H$89,Calc!$F$15),INDEX(Calc!H$50:H$64,Calc!$D$15)))) | AA8: =IF(AB8="","",N(AB7)*(1+Start!$E$24/12)-AB8) | AB8: =IF(OR(OR(Calc!$B$4=0,$B8>IF(Start!$D$10="Avalanche",Calc!$B$3,Calc!$B$2)),Calc!$B$16=0),"",IF(N(AB7)<=0.005,"",IF(Start!$D$10="Avalanche",INDEX(Calc!H$75:H$89,Calc!$F$16),INDEX(Calc!H$50:H$64,Calc!$D$16)))) | AC8: =IF(AD8="","",N(AD7)*(1+Start!$E$25/12)-AD8) | AD8: =IF(OR(OR(Calc!$B$4=0,$B8>IF(Start!$D$10="Avalanche",Calc!$B$3,Calc!$B$2)),Calc!$B$17=0),"",IF(N(AD7)<=0.005,"",IF(Start!$D$10="Avalanche",INDEX(Calc!H$75:H$89,Calc!$F$17),INDEX(Calc!H$50:H$64,Calc!$D$17)))) | AE8: =IF(AF8="","",N(AF7)*(1+Start!$E$26/12)-AF8) | AF8: =IF(OR(OR(Calc!$B$4=0,$B8>IF(Start!$D$10="Avalanche",Calc!$B$3,Calc!$B$2)),Calc!$B$18=0),"",IF(N(AF7)<=0.005,"",IF(Start!$D$10="Avalanche",INDEX(Calc!H$75:H$89,Calc!$F$18),INDEX(Calc!H$50:H$64,Calc!$D$18)))) | AG8: =IF(AH8="","",N(AH7)*(1+Start!$E$27/12)-AH8) | AH8: =IF(OR(OR(Calc!$B$4=0,$B8>IF(Start!$D$10="Avalanche",Calc!$B$3,Calc!$B$2)),Calc!$B$19=0),"",IF(N(AH7)<=0.005,"",IF(Start!$D$10="Avalanche",INDEX(Calc!H$75:H$89,Calc!$F$19),INDEX(Calc!H$50:H$64,Calc!$D$19)))) | AI8: =IF(AJ8="","",N(AJ7)*(1+Start!$E$28/12)-AJ8) | AJ8: =IF(OR(OR(Calc!$B$4=0,$B8>IF(Start!$D$10="Avalanche",Calc!$B$3,Calc!$B$2)),Calc!$B$20=0),"",IF(N(AJ7)<=0.005,"",IF(Start!$D$10="Avalanche",INDEX(Calc!H$75:H$89,Calc!$F$20),INDEX(Calc!H$50:H$64,Calc!$D$20))))
B9: 3 | C9: =IF(Calc!$B$4=0,"",EDATE(Start!$D$11,2)) | D9: =IF(OR(Calc!$B$4=0,$B9>IF(Start!$D$10="Avalanche",Calc!$B$3,Calc!$B$2)),"",SUM(G9,I9,K9,M9,O9,Q9,S9,U9,W9,Y9,AA9,AC9,AE9,AG9,AI9)) | E9: =IF(OR(Calc!$B$4=0,$B9>IF(Start!$D$10="Avalanche",Calc!$B$3,Calc!$B$2)),"",IF(Start!$D$10="Avalanche",Calc!I$72,Calc!I$47)) | F9: =IF(Calc!$B$4=0,"",IF($B9>IF(Start!$D$10="Avalanche",Calc!$B$3,Calc!$B$2),NA(),SUM(H9,J9,L9,N9,P9,R9,T9,V9,X9,Z9,AB9,AD9,AF9,AH9,AJ9))) | G9: =IF(H9="","",N(H8)*(1+Start!$E$14/12)-H9) | H9: =IF(OR(OR(Calc!$B$4=0,$B9>IF(Start!$D$10="Avalanche",Calc!$B$3,Calc!$B$2)),Calc!$B$6=0),"",IF(N(H8)<=0.005,"",IF(Start!$D$10="Avalanche",INDEX(Calc!K$75:K$89,Calc!$F$6),INDEX(Calc!K$50:K$64,Calc!$D$6)))) | I9: =IF(J9="","",N(J8)*(1+Start!$E$15/12)-J9) | J9: =IF(OR(OR(Calc!$B$4=0,$B9>IF(Start!$D$10="Avalanche",Calc!$B$3,Calc!$B$2)),Calc!$B$7=0),"",IF(N(J8)<=0.005,"",IF(Start!$D$10="Avalanche",INDEX(Calc!K$75:K$89,Calc!$F$7),INDEX(Calc!K$50:K$64,Calc!$D$7)))) | K9: =IF(L9="","",N(L8)*(1+Start!$E$16/12)-L9) | L9: =IF(OR(OR(Calc!$B$4=0,$B9>IF(Start!$D$10="Avalanche",Calc!$B$3,Calc!$B$2)),Calc!$B$8=0),"",IF(N(L8)<=0.005,"",IF(Start!$D$10="Avalanche",INDEX(Calc!K$75:K$89,Calc!$F$8),INDEX(Calc!K$50:K$64,Calc!$D$8)))) | M9: =IF(N9="","",N(N8)*(1+Start!$E$17/12)-N9) | N9: =IF(OR(OR(Calc!$B$4=0,$B9>IF(Start!$D$10="Avalanche",Calc!$B$3,Calc!$B$2)),Calc!$B$9=0),"",IF(N(N8)<=0.005,"",IF(Start!$D$10="Avalanche",INDEX(Calc!K$75:K$89,Calc!$F$9),INDEX(Calc!K$50:K$64,Calc!$D$9)))) | O9: =IF(P9="","",N(P8)*(1+Start!$E$18/12)-P9) | P9: =IF(OR(OR(Calc!$B$4=0,$B9>IF(Start!$D$10="Avalanche",Calc!$B$3,Calc!$B$2)),Calc!$B$10=0),"",IF(N(P8)<=0.005,"",IF(Start!$D$10="Avalanche",INDEX(Calc!K$75:K$89,Calc!$F$10),INDEX(Calc!K$50:K$64,Calc!$D$10)))) | Q9: =IF(R9="","",N(R8)*(1+Start!$E$19/12)-R9) | R9: =IF(OR(OR(Calc!$B$4=0,$B9>IF(Start!$D$10="Avalanche",Calc!$B$3,Calc!$B$2)),Calc!$B$11=0),"",IF(N(R8)<=0.005,"",IF(Start!$D$10="Avalanche",INDEX(Calc!K$75:K$89,Calc!$F$11),INDEX(Calc!K$50:K$64,Calc!$D$11)))) | S9: =IF(T9="","",N(T8)*(1+Start!$E$20/12)-T9) | T9: =IF(OR(OR(Calc!$B$4=0,$B9>IF(Start!$D$10="Avalanche",Calc!$B$3,Calc!$B$2)),Calc!$B$12=0),"",IF(N(T8)<=0.005,"",IF(Start!$D$10="Avalanche",INDEX(Calc!K$75:K$89,Calc!$F$12),INDEX(Calc!K$50:K$64,Calc!$D$12)))) | U9: =IF(V9="","",N(V8)*(1+Start!$E$21/12)-V9) | V9: =IF(OR(OR(Calc!$B$4=0,$B9>IF(Start!$D$10="Avalanche",Calc!$B$3,Calc!$B$2)),Calc!$B$13=0),"",IF(N(V8)<=0.005,"",IF(Start!$D$10="Avalanche",INDEX(Calc!K$75:K$89,Calc!$F$13),INDEX(Calc!K$50:K$64,Calc!$D$13)))) | W9: =IF(X9="","",N(X8)*(1+Start!$E$22/12)-X9) | X9: =IF(OR(OR(Calc!$B$4=0,$B9>IF(Start!$D$10="Avalanche",Calc!$B$3,Calc!$B$2)),Calc!$B$14=0),"",IF(N(X8)<=0.005,"",IF(Start!$D$10="Avalanche",INDEX(Calc!K$75:K$89,Calc!$F$14),INDEX(Calc!K$50:K$64,Calc!$D$14)))) | Y9: =IF(Z9="","",N(Z8)*(1+Start!$E$23/12)-Z9) | Z9: =IF(OR(OR(Calc!$B$4=0,$B9>IF(Start!$D$10="Avalanche",Calc!$B$3,Calc!$B$2)),Calc!$B$15=0),"",IF(N(Z8)<=0.005,"",IF(Start!$D$10="Avalanche",INDEX(Calc!K$75:K$89,Calc!$F$15),INDEX(Calc!K$50:K$64,Calc!$D$15)))) | AA9: =IF(AB9="","",N(AB8)*(1+Start!$E$24/12)-AB9) | AB9: =IF(OR(OR(Calc!$B$4=0,$B9>IF(Start!$D$10="Avalanche",Calc!$B$3,Calc!$B$2)),Calc!$B$16=0),"",IF(N(AB8)<=0.005,"",IF(Start!$D$10="Avalanche",INDEX(Calc!K$75:K$89,Calc!$F$16),INDEX(Calc!K$50:K$64,Calc!$D$16)))) | AC9: =IF(AD9="","",N(AD8)*(1+Start!$E$25/12)-AD9) | AD9: =IF(OR(OR(Calc!$B$4=0,$B9>IF(Start!$D$10="Avalanche",Calc!$B$3,Calc!$B$2)),Calc!$B$17=0),"",IF(N(AD8)<=0.005,"",IF(Start!$D$10="Avalanche",INDEX(Calc!K$75:K$89,Calc!$F$17),INDEX(Calc!K$50:K$64,Calc!$D$17)))) | AE9: =IF(AF9="","",N(AF8)*(1+Start!$E$26/12)-AF9) | AF9: =IF(OR(OR(Calc!$B$4=0,$B9>IF(Start!$D$10="Avalanche",Calc!$B$3,Calc!$B$2)),Calc!$B$18=0),"",IF(N(AF8)<=0.005,"",IF(Start!$D$10="Avalanche",INDEX(Calc!K$75:K$89,Calc!$F$18),INDEX(Calc!K$50:K$64,Calc!$D$18)))) | AG9: =IF(AH9="","",N(AH8)*(1+Start!$E$27/12)-AH9) | AH9: =IF(OR(OR(Calc!$B$4=0,$B9>IF(Start!$D$10="Avalanche",Calc!$B$3,Calc!$B$2)),Calc!$B$19=0),"",IF(N(AH8)<=0.005,"",IF(Start!$D$10="Avalanche",INDEX(Calc!K$75:K$89,Calc!$F$19),INDEX(Calc!K$50:K$64,Calc!$D$19)))) | AI9: =IF(AJ9="","",N(AJ8)*(1+Start!$E$28/12)-AJ9) | AJ9: =IF(OR(OR(Calc!$B$4=0,$B9>IF(Start!$D$10="Avalanche",Calc!$B$3,Calc!$B$2)),Calc!$B$20=0),"",IF(N(AJ8)<=0.005,"",IF(Start!$D$10="Avalanche",INDEX(Calc!K$75:K$89,Calc!$F$20),INDEX(Calc!K$50:K$64,Calc!$D$20))))
B10: 4 | C10: =IF(Calc!$B$4=0,"",EDATE(Start!$D$11,3)) | D10: =IF(OR(Calc!$B$4=0,$B10>IF(Start!$D$10="Avalanche",Calc!$B$3,Calc!$B$2)),"",SUM(G10,I10,K10,M10,O10,Q10,S10,U10,W10,Y10,AA10,AC10,AE10,AG10,AI10)) | E10: =IF(OR(Calc!$B$4=0,$B10>IF(Start!$D$10="Avalanche",Calc!$B$3,Calc!$B$2)),"",IF(Start!$D$10="Avalanche",Calc!L$72,Calc!L$47)) | F10: =IF(Calc!$B$4=0,"",IF($B10>IF(Start!$D$10="Avalanche",Calc!$B$3,Calc!$B$2),NA(),SUM(H10,J10,L10,N10,P10,R10,T10,V10,X10,Z10,AB10,AD10,AF10,AH10,AJ10))) | G10: =IF(H10="","",N(H9)*(1+Start!$E$14/12)-H10) | H10: =IF(OR(OR(Calc!$B$4=0,$B10>IF(Start!$D$10="Avalanche",Calc!$B$3,Calc!$B$2)),Calc!$B$6=0),"",IF(N(H9)<=0.005,"",IF(Start!$D$10="Avalanche",INDEX(Calc!N$75:N$89,Calc!$F$6),INDEX(Calc!N$50:N$64,Calc!$D$6)))) | I10: =IF(J10="","",N(J9)*(1+Start!$E$15/12)-J10) | J10: =IF(OR(OR(Calc!$B$4=0,$B10>IF(Start!$D$10="Avalanche",Calc!$B$3,Calc!$B$2)),Calc!$B$7=0),"",IF(N(J9)<=0.005,"",IF(Start!$D$10="Avalanche",INDEX(Calc!N$75:N$89,Calc!$F$7),INDEX(Calc!N$50:N$64,Calc!$D$7)))) | K10: =IF(L10="","",N(L9)*(1+Start!$E$16/12)-L10) | L10: =IF(OR(OR(Calc!$B$4=0,$B10>IF(Start!$D$10="Avalanche",Calc!$B$3,Calc!$B$2)),Calc!$B$8=0),"",IF(N(L9)<=0.005,"",IF(Start!$D$10="Avalanche",INDEX(Calc!N$75:N$89,Calc!$F$8),INDEX(Calc!N$50:N$64,Calc!$D$8)))) | M10: =IF(N10="","",N(N9)*(1+Start!$E$17/12)-N10) | N10: =IF(OR(OR(Calc!$B$4=0,$B10>IF(Start!$D$10="Avalanche",Calc!$B$3,Calc!$B$2)),Calc!$B$9=0),"",IF(N(N9)<=0.005,"",IF(Start!$D$10="Avalanche",INDEX(Calc!N$75:N$89,Calc!$F$9),INDEX(Calc!N$50:N$64,Calc!$D$9)))) | O10: =IF(P10="","",N(P9)*(1+Start!$E$18/12)-P10) | P10: =IF(OR(OR(Calc!$B$4=0,$B10>IF(Start!$D$10="Avalanche",Calc!$B$3,Calc!$B$2)),Calc!$B$10=0),"",IF(N(P9)<=0.005,"",IF(Start!$D$10="Avalanche",INDEX(Calc!N$75:N$89,Calc!$F$10),INDEX(Calc!N$50:N$64,Calc!$D$10)))) | Q10: =IF(R10="","",N(R9)*(1+Start!$E$19/12)-R10) | R10: =IF(OR(OR(Calc!$B$4=0,$B10>IF(Start!$D$10="Avalanche",Calc!$B$3,Calc!$B$2)),Calc!$B$11=0),"",IF(N(R9)<=0.005,"",IF(Start!$D$10="Avalanche",INDEX(Calc!N$75:N$89,Calc!$F$11),INDEX(Calc!N$50:N$64,Calc!$D$11)))) | S10: =IF(T10="","",N(T9)*(1+Start!$E$20/12)-T10) | T10: =IF(OR(OR(Calc!$B$4=0,$B10>IF(Start!$D$10="Avalanche",Calc!$B$3,Calc!$B$2)),Calc!$B$12=0),"",IF(N(T9)<=0.005,"",IF(Start!$D$10="Avalanche",INDEX(Calc!N$75:N$89,Calc!$F$12),INDEX(Calc!N$50:N$64,Calc!$D$12)))) | U10: =IF(V10="","",N(V9)*(1+Start!$E$21/12)-V10) | V10: =IF(OR(OR(Calc!$B$4=0,$B10>IF(Start!$D$10="Avalanche",Calc!$B$3,Calc!$B$2)),Calc!$B$13=0),"",IF(N(V9)<=0.005,"",IF(Start!$D$10="Avalanche",INDEX(Calc!N$75:N$89,Calc!$F$13),INDEX(Calc!N$50:N$64,Calc!$D$13)))) | W10: =IF(X10="","",N(X9)*(1+Start!$E$22/12)-X10) | X10: =IF(OR(OR(Calc!$B$4=0,$B10>IF(Start!$D$10="Avalanche",Calc!$B$3,Calc!$B$2)),Calc!$B$14=0),"",IF(N(X9)<=0.005,"",IF(Start!$D$10="Avalanche",INDEX(Calc!N$75:N$89,Calc!$F$14),INDEX(Calc!N$50:N$64,Calc!$D$14)))) | Y10: =IF(Z10="","",N(Z9)*(1+Start!$E$23/12)-Z10) | Z10: =IF(OR(OR(Calc!$B$4=0,$B10>IF(Start!$D$10="Avalanche",Calc!$B$3,Calc!$B$2)),Calc!$B$15=0),"",IF(N(Z9)<=0.005,"",IF(Start!$D$10="Avalanche",INDEX(Calc!N$75:N$89,Calc!$F$15),INDEX(Calc!N$50:N$64,Calc!$D$15)))) | AA10: =IF(AB10="","",N(AB9)*(1+Start!$E$24/12)-AB10) | AB10: =IF(OR(OR(Calc!$B$4=0,$B10>IF(Start!$D$10="Avalanche",Calc!$B$3,Calc!$B$2)),Calc!$B$16=0),"",IF(N(AB9)<=0.005,"",IF(Start!$D$10="Avalanche",INDEX(Calc!N$75:N$89,Calc!$F$16),INDEX(Calc!N$50:N$64,Calc!$D$16)))) | AC10: =IF(AD10="","",N(AD9)*(1+Start!$E$25/12)-AD10) | AD10: =IF(OR(OR(Calc!$B$4=0,$B10>IF(Start!$D$10="Avalanche",Calc!$B$3,Calc!$B$2)),Calc!$B$17=0),"",IF(N(AD9)<=0.005,"",IF(Start!$D$10="Avalanche",INDEX(Calc!N$75:N$89,Calc!$F$17),INDEX(Calc!N$50:N$64,Calc!$D$17)))) | AE10: =IF(AF10="","",N(AF9)*(1+Start!$E$26/12)-AF10) | AF10: =IF(OR(OR(Calc!$B$4=0,$B10>IF(Start!$D$10="Avalanche",Calc!$B$3,Calc!$B$2)),Calc!$B$18=0),"",IF(N(AF9)<=0.005,"",IF(Start!$D$10="Avalanche",INDEX(Calc!N$75:N$89,Calc!$F$18),INDEX(Calc!N$50:N$64,Calc!$D$18)))) | AG10: =IF(AH10="","",N(AH9)*(1+Start!$E$27/12)-AH10) | AH10: =IF(OR(OR(Calc!$B$4=0,$B10>IF(Start!$D$10="Avalanche",Calc!$B$3,Calc!$B$2)),Calc!$B$19=0),"",IF(N(AH9)<=0.005,"",IF(Start!$D$10="Avalanche",INDEX(Calc!N$75:N$89,Calc!$F$19),INDEX(Calc!N$50:N$64,Calc!$D$19)))) | AI10: =IF(AJ10="","",N(AJ9)*(1+Start!$E$28/12)-AJ10) | AJ10: =IF(OR(OR(Calc!$B$4=0,$B10>IF(Start!$D$10="Avalanche",Calc!$B$3,Calc!$B$2)),Calc!$B$20=0),"",IF(N(AJ9)<=0.005,"",IF(Start!$D$10="Avalanche",INDEX(Calc!N$75:N$89,Calc!$F$20),INDEX(Calc!N$50:N$64,Calc!$D$20))))
B11: 5 | C11: =IF(Calc!$B$4=0,"",EDATE(Start!$D$11,4)) | D11: =IF(OR(Calc!$B$4=0,$B11>IF(Start!$D$10="Avalanche",Calc!$B$3,Calc!$B$2)),"",SUM(G11,I11,K11,M11,O11,Q11,S11,U11,W11,Y11,AA11,AC11,AE11,AG11,AI11)) | E11: =IF(OR(Calc!$B$4=0,$B11>IF(Start!$D$10="Avalanche",Calc!$B$3,Calc!$B$2)),"",IF(Start!$D$10="Avalanche",Calc!O$72,Calc!O$47)) | F11: =IF(Calc!$B$4=0,"",IF($B11>IF(Start!$D$10="Avalanche",Calc!$B$3,Calc!$B$2),NA(),SUM(H11,J11,L11,N11,P11,R11,T11,V11,X11,Z11,AB11,AD11,AF11,AH11,AJ11))) | G11: =IF(H11="","",N(H10)*(1+Start!$E$14/12)-H11) | H11: =IF(OR(OR(Calc!$B$4=0,$B11>IF(Start!$D$10="Avalanche",Calc!$B$3,Calc!$B$2)),Calc!$B$6=0),"",IF(N(H10)<=0.005,"",IF(Start!$D$10="Avalanche",INDEX(Calc!Q$75:Q$89,Calc!$F$6),INDEX(Calc!Q$50:Q$64,Calc!$D$6)))) | I11: =IF(J11="","",N(J10)*(1+Start!$E$15/12)-J11) | J11: =IF(OR(OR(Calc!$B$4=0,$B11>IF(Start!$D$10="Avalanche",Calc!$B$3,Calc!$B$2)),Calc!$B$7=0),"",IF(N(J10)<=0.005,"",IF(Start!$D$10="Avalanche",INDEX(Calc!Q$75:Q$89,Calc!$F$7),INDEX(Calc!Q$50:Q$64,Calc!$D$7)))) | K11: =IF(L11="","",N(L10)*(1+Start!$E$16/12)-L11) | L11: =IF(OR(OR(Calc!$B$4=0,$B11>IF(Start!$D$10="Avalanche",Calc!$B$3,Calc!$B$2)),Calc!$B$8=0),"",IF(N(L10)<=0.005,"",IF(Start!$D$10="Avalanche",INDEX(Calc!Q$75:Q$89,Calc!$F$8),INDEX(Calc!Q$50:Q$64,Calc!$D$8)))) | M11: =IF(N11="","",N(N10)*(1+Start!$E$17/12)-N11) | N11: =IF(OR(OR(Calc!$B$4=0,$B11>IF(Start!$D$10="Avalanche",Calc!$B$3,Calc!$B$2)),Calc!$B$9=0),"",IF(N(N10)<=0.005,"",IF(Start!$D$10="Avalanche",INDEX(Calc!Q$75:Q$89,Calc!$F$9),INDEX(Calc!Q$50:Q$64,Calc!$D$9)))) | O11: =IF(P11="","",N(P10)*(1+Start!$E$18/12)-P11) | P11: =IF(OR(OR(Calc!$B$4=0,$B11>IF(Start!$D$10="Avalanche",Calc!$B$3,Calc!$B$2)),Calc!$B$10=0),"",IF(N(P10)<=0.005,"",IF(Start!$D$10="Avalanche",INDEX(Calc!Q$75:Q$89,Calc!$F$10),INDEX(Calc!Q$50:Q$64,Calc!$D$10)))) | Q11: =IF(R11="","",N(R10)*(1+Start!$E$19/12)-R11) | R11: =IF(OR(OR(Calc!$B$4=0,$B11>IF(Start!$D$10="Avalanche",Calc!$B$3,Calc!$B$2)),Calc!$B$11=0),"",IF(N(R10)<=0.005,"",IF(Start!$D$10="Avalanche",INDEX(Calc!Q$75:Q$89,Calc!$F$11),INDEX(Calc!Q$50:Q$64,Calc!$D$11)))) | S11: =IF(T11="","",N(T10)*(1+Start!$E$20/12)-T11) | T11: =IF(OR(OR(Calc!$B$4=0,$B11>IF(Start!$D$10="Avalanche",Calc!$B$3,Calc!$B$2)),Calc!$B$12=0),"",IF(N(T10)<=0.005,"",IF(Start!$D$10="Avalanche",INDEX(Calc!Q$75:Q$89,Calc!$F$12),INDEX(Calc!Q$50:Q$64,Calc!$D$12)))) | U11: =IF(V11="","",N(V10)*(1+Start!$E$21/12)-V11) | V11: =IF(OR(OR(Calc!$B$4=0,$B11>IF(Start!$D$10="Avalanche",Calc!$B$3,Calc!$B$2)),Calc!$B$13=0),"",IF(N(V10)<=0.005,"",IF(Start!$D$10="Avalanche",INDEX(Calc!Q$75:Q$89,Calc!$F$13),INDEX(Calc!Q$50:Q$64,Calc!$D$13)))) | W11: =IF(X11="","",N(X10)*(1+Start!$E$22/12)-X11) | X11: =IF(OR(OR(Calc!$B$4=0,$B11>IF(Start!$D$10="Avalanche",Calc!$B$3,Calc!$B$2)),Calc!$B$14=0),"",IF(N(X10)<=0.005,"",IF(Start!$D$10="Avalanche",INDEX(Calc!Q$75:Q$89,Calc!$F$14),INDEX(Calc!Q$50:Q$64,Calc!$D$14)))) | Y11: =IF(Z11="","",N(Z10)*(1+Start!$E$23/12)-Z11) | Z11: =IF(OR(OR(Calc!$B$4=0,$B11>IF(Start!$D$10="Avalanche",Calc!$B$3,Calc!$B$2)),Calc!$B$15=0),"",IF(N(Z10)<=0.005,"",IF(Start!$D$10="Avalanche",INDEX(Calc!Q$75:Q$89,Calc!$F$15),INDEX(Calc!Q$50:Q$64,Calc!$D$15)))) | AA11: =IF(AB11="","",N(AB10)*(1+Start!$E$24/12)-AB11) | AB11: =IF(OR(OR(Calc!$B$4=0,$B11>IF(Start!$D$10="Avalanche",Calc!$B$3,Calc!$B$2)),Calc!$B$16=0),"",IF(N(AB10)<=0.005,"",IF(Start!$D$10="Avalanche",INDEX(Calc!Q$75:Q$89,Calc!$F$16),INDEX(Calc!Q$50:Q$64,Calc!$D$16)))) | AC11: =IF(AD11="","",N(AD10)*(1+Start!$E$25/12)-AD11) | AD11: =IF(OR(OR(Calc!$B$4=0,$B11>IF(Start!$D$10="Avalanche",Calc!$B$3,Calc!$B$2)),Calc!$B$17=0),"",IF(N(AD10)<=0.005,"",IF(Start!$D$10="Avalanche",INDEX(Calc!Q$75:Q$89,Calc!$F$17),INDEX(Calc!Q$50:Q$64,Calc!$D$17)))) | AE11: =IF(AF11="","",N(AF10)*(1+Start!$E$26/12)-AF11) | AF11: =IF(OR(OR(Calc!$B$4=0,$B11>IF(Start!$D$10="Avalanche",Calc!$B$3,Calc!$B$2)),Calc!$B$18=0),"",IF(N(AF10)<=0.005,"",IF(Start!$D$10="Avalanche",INDEX(Calc!Q$75:Q$89,Calc!$F$18),INDEX(Calc!Q$50:Q$64,Calc!$D$18)))) | AG11: =IF(AH11="","",N(AH10)*(1+Start!$E$27/12)-AH11) | AH11: =IF(OR(OR(Calc!$B$4=0,$B11>IF(Start!$D$10="Avalanche",Calc!$B$3,Calc!$B$2)),Calc!$B$19=0),"",IF(N(AH10)<=0.005,"",IF(Start!$D$10="Avalanche",INDEX(Calc!Q$75:Q$89,Calc!$F$19),INDEX(Calc!Q$50:Q$64,Calc!$D$19)))) | AI11: =IF(AJ11="","",N(AJ10)*(1+Start!$E$28/12)-AJ11) | AJ11: =IF(OR(OR(Calc!$B$4=0,$B11>IF(Start!$D$10="Avalanche",Calc!$B$3,Calc!$B$2)),Calc!$B$20=0),"",IF(N(AJ10)<=0.005,"",IF(Start!$D$10="Avalanche",INDEX(Calc!Q$75:Q$89,Calc!$F$20),INDEX(Calc!Q$50:Q$64,Calc!$D$20))))
B12: 6 | C12: =IF(Calc!$B$4=0,"",EDATE(Start!$D$11,5)) | D12: =IF(OR(Calc!$B$4=0,$B12>IF(Start!$D$10="Avalanche",Calc!$B$3,Calc!$B$2)),"",SUM(G12,I12,K12,M12,O12,Q12,S12,U12,W12,Y12,AA12,AC12,AE12,AG12,AI12)) | E12: =IF(OR(Calc!$B$4=0,$B12>IF(Start!$D$10="Avalanche",Calc!$B$3,Calc!$B$2)),"",IF(Start!$D$10="Avalanche",Calc!R$72,Calc!R$47)) | F12: =IF(Calc!$B$4=0,"",IF($B12>IF(Start!$D$10="Avalanche",Calc!$B$3,Calc!$B$2),NA(),SUM(H12,J12,L12,N12,P12,R12,T12,V12,X12,Z12,AB12,AD12,AF12,AH12,AJ12))) | G12: =IF(H12="","",N(H11)*(1+Start!$E$14/12)-H12) | H12: =IF(OR(OR(Calc!$B$4=0,$B12>IF(Start!$D$10="Avalanche",Calc!$B$3,Calc!$B$2)),Calc!$B$6=0),"",IF(N(H11)<=0.005,"",IF(Start!$D$10="Avalanche",INDEX(Calc!T$75:T$89,Calc!$F$6),INDEX(Calc!T$50:T$64,Calc!$D$6)))) | I12: =IF(J12="","",N(J11)*(1+Start!$E$15/12)-J12) | J12: =IF(OR(OR(Calc!$B$4=0,$B12>IF(Start!$D$10="Avalanche",Calc!$B$3,Calc!$B$2)),Calc!$B$7=0),"",IF(N(J11)<=0.005,"",IF(Start!$D$10="Avalanche",INDEX(Calc!T$75:T$89,Calc!$F$7),INDEX(Calc!T$50:T$64,Calc!$D$7)))) | K12: =IF(L12="","",N(L11)*(1+Start!$E$16/12)-L12) | L12: =IF(OR(OR(Calc!$B$4=0,$B12>IF(Start!$D$10="Avalanche",Calc!$B$3,Calc!$B$2)),Calc!$B$8=0),"",IF(N(L11)<=0.005,"",IF(Start!$D$10="Avalanche",INDEX(Calc!T$75:T$89,Calc!$F$8),INDEX(Calc!T$50:T$64,Calc!$D$8)))) | M12: =IF(N12="","",N(N11)*(1+Start!$E$17/12)-N12) | N12: =IF(OR(OR(Calc!$B$4=0,$B12>IF(Start!$D$10="Avalanche",Calc!$B$3,Calc!$B$2)),Calc!$B$9=0),"",IF(N(N11)<=0.005,"",IF(Start!$D$10="Avalanche",INDEX(Calc!T$75:T$89,Calc!$F$9),INDEX(Calc!T$50:T$64,Calc!$D$9)))) | O12: =IF(P12="","",N(P11)*(1+Start!$E$18/12)-P12) | P12: =IF(OR(OR(Calc!$B$4=0,$B12>IF(Start!$D$10="Avalanche",Calc!$B$3,Calc!$B$2)),Calc!$B$10=0),"",IF(N(P11)<=0.005,"",IF(Start!$D$10="Avalanche",INDEX(Calc!T$75:T$89,Calc!$F$10),INDEX(Calc!T$50:T$64,Calc!$D$10)))) | Q12: =IF(R12="","",N(R11)*(1+Start!$E$19/12)-R12) | R12: =IF(OR(OR(Calc!$B$4=0,$B12>IF(Start!$D$10="Avalanche",Calc!$B$3,Calc!$B$2)),Calc!$B$11=0),"",IF(N(R11)<=0.005,"",IF(Start!$D$10="Avalanche",INDEX(Calc!T$75:T$89,Calc!$F$11),INDEX(Calc!T$50:T$64,Calc!$D$11)))) | S12: =IF(T12="","",N(T11)*(1+Start!$E$20/12)-T12) | T12: =IF(OR(OR(Calc!$B$4=0,$B12>IF(Start!$D$10="Avalanche",Calc!$B$3,Calc!$B$2)),Calc!$B$12=0),"",IF(N(T11)<=0.005,"",IF(Start!$D$10="Avalanche",INDEX(Calc!T$75:T$89,Calc!$F$12),INDEX(Calc!T$50:T$64,Calc!$D$12)))) | U12: =IF(V12="","",N(V11)*(1+Start!$E$21/12)-V12) | V12: =IF(OR(OR(Calc!$B$4=0,$B12>IF(Start!$D$10="Avalanche",Calc!$B$3,Calc!$B$2)),Calc!$B$13=0),"",IF(N(V11)<=0.005,"",IF(Start!$D$10="Avalanche",INDEX(Calc!T$75:T$89,Calc!$F$13),INDEX(Calc!T$50:T$64,Calc!$D$13)))) | W12: =IF(X12="","",N(X11)*(1+Start!$E$22/12)-X12) | X12: =IF(OR(OR(Calc!$B$4=0,$B12>IF(Start!$D$10="Avalanche",Calc!$B$3,Calc!$B$2)),Calc!$B$14=0),"",IF(N(X11)<=0.005,"",IF(Start!$D$10="Avalanche",INDEX(Calc!T$75:T$89,Calc!$F$14),INDEX(Calc!T$50:T$64,Calc!$D$14)))) | Y12: =IF(Z12="","",N(Z11)*(1+Start!$E$23/12)-Z12) | Z12: =IF(OR(OR(Calc!$B$4=0,$B12>IF(Start!$D$10="Avalanche",Calc!$B$3,Calc!$B$2)),Calc!$B$15=0),"",IF(N(Z11)<=0.005,"",IF(Start!$D$10="Avalanche",INDEX(Calc!T$75:T$89,Calc!$F$15),INDEX(Calc!T$50:T$64,Calc!$D$15)))) | AA12: =IF(AB12="","",N(AB11)*(1+Start!$E$24/12)-AB12) | AB12: =IF(OR(OR(Calc!$B$4=0,$B12>IF(Start!$D$10="Avalanche",Calc!$B$3,Calc!$B$2)),Calc!$B$16=0),"",IF(N(AB11)<=0.005,"",IF(Start!$D$10="Avalanche",INDEX(Calc!T$75:T$89,Calc!$F$16),INDEX(Calc!T$50:T$64,Calc!$D$16)))) | AC12: =IF(AD12="","",N(AD11)*(1+Start!$E$25/12)-AD12) | AD12: =IF(OR(OR(Calc!$B$4=0,$B12>IF(Start!$D$10="Avalanche",Calc!$B$3,Calc!$B$2)),Calc!$B$17=0),"",IF(N(AD11)<=0.005,"",IF(Start!$D$10="Avalanche",INDEX(Calc!T$75:T$89,Calc!$F$17),INDEX(Calc!T$50:T$64,Calc!$D$17)))) | AE12: =IF(AF12="","",N(AF11)*(1+Start!$E$26/12)-AF12) | AF12: =IF(OR(OR(Calc!$B$4=0,$B12>IF(Start!$D$10="Avalanche",Calc!$B$3,Calc!$B$2)),Calc!$B$18=0),"",IF(N(AF11)<=0.005,"",IF(Start!$D$10="Avalanche",INDEX(Calc!T$75:T$89,Calc!$F$18),INDEX(Calc!T$50:T$64,Calc!$D$18)))) | AG12: =IF(AH12="","",N(AH11)*(1+Start!$E$27/12)-AH12) | AH12: =IF(OR(OR(Calc!$B$4=0,$B12>IF(Start!$D$10="Avalanche",Calc!$B$3,Calc!$B$2)),Calc!$B$19=0),"",IF(N(AH11)<=0.005,"",IF(Start!$D$10="Avalanche",INDEX(Calc!T$75:T$89,Calc!$F$19),INDEX(Calc!T$50:T$64,Calc!$D$19)))) | AI12: =IF(AJ12="","",N(AJ11)*(1+Start!$E$28/12)-AJ12) | AJ12: =IF(OR(OR(Calc!$B$4=0,$B12>IF(Start!$D$10="Avalanche",Calc!$B$3,Calc!$B$2)),Calc!$B$20=0),"",IF(N(AJ11)<=0.005,"",IF(Start!$D$10="Avalanche",INDEX(Calc!T$75:T$89,Calc!$F$20),INDEX(Calc!T$50:T$64,Calc!$D$20))))
B13: 7 | C13: =IF(Calc!$B$4=0,"",EDATE(Start!$D$11,6)) | D13: =IF(OR(Calc!$B$4=0,$B13>IF(Start!$D$10="Avalanche",Calc!$B$3,Calc!$B$2)),"",SUM(G13,I13,K13,M13,O13,Q13,S13,U13,W13,Y13,AA13,AC13,AE13,AG13,AI13)) | E13: =IF(OR(Calc!$B$4=0,$B13>IF(Start!$D$10="Avalanche",Calc!$B$3,Calc!$B$2)),"",IF(Start!$D$10="Avalanche",Calc!U$72,Calc!U$47)) | F13: =IF(Calc!$B$4=0,"",IF($B13>IF(Start!$D$10="Avalanche",Calc!$B$3,Calc!$B$2),NA(),SUM(H13,J13,L13,N13,P13,R13,T13,V13,X13,Z13,AB13,AD13,AF13,AH13,AJ13))) | G13: =IF(H13="","",N(H12)*(1+Start!$E$14/12)-H13) | H13: =IF(OR(OR(Calc!$B$4=0,$B13>IF(Start!$D$10="Avalanche",Calc!$B$3,Calc!$B$2)),Calc!$B$6=0),"",IF(N(H12)<=0.005,"",IF(Start!$D$10="Avalanche",INDEX(Calc!W$75:W$89,Calc!$F$6),INDEX(Calc!W$50:W$64,Calc!$D$6)))) | I13: =IF(J13="","",N(J12)*(1+Start!$E$15/12)-J13) | J13: =IF(OR(OR(Calc!$B$4=0,$B13>IF(Start!$D$10="Avalanche",Calc!$B$3,Calc!$B$2)),Calc!$B$7=0),"",IF(N(J12)<=0.005,"",IF(Start!$D$10="Avalanche",INDEX(Calc!W$75:W$89,Calc!$F$7),INDEX(Calc!W$50:W$64,Calc!$D$7)))) | K13: =IF(L13="","",N(L12)*(1+Start!$E$16/12)-L13) | L13: =IF(OR(OR(Calc!$B$4=0,$B13>IF(Start!$D$10="Avalanche",Calc!$B$3,Calc!$B$2)),Calc!$B$8=0),"",IF(N(L12)<=0.005,"",IF(Start!$D$10="Avalanche",INDEX(Calc!W$75:W$89,Calc!$F$8),INDEX(Calc!W$50:W$64,Calc!$D$8)))) | M13: =IF(N13="","",N(N12)*(1+Start!$E$17/12)-N13) | N13: =IF(OR(OR(Calc!$B$4=0,$B13>IF(Start!$D$10="Avalanche",Calc!$B$3,Calc!$B$2)),Calc!$B$9=0),"",IF(N(N12)<=0.005,"",IF(Start!$D$10="Avalanche",INDEX(Calc!W$75:W$89,Calc!$F$9),INDEX(Calc!W$50:W$64,Calc!$D$9)))) | O13: =IF(P13="","",N(P12)*(1+Start!$E$18/12)-P13) | P13: =IF(OR(OR(Calc!$B$4=0,$B13>IF(Start!$D$10="Avalanche",Calc!$B$3,Calc!$B$2)),Calc!$B$10=0),"",IF(N(P12)<=0.005,"",IF(Start!$D$10="Avalanche",INDEX(Calc!W$75:W$89,Calc!$F$10),INDEX(Calc!W$50:W$64,Calc!$D$10)))) | Q13: =IF(R13="","",N(R12)*(1+Start!$E$19/12)-R13) | R13: =IF(OR(OR(Calc!$B$4=0,$B13>IF(Start!$D$10="Avalanche",Calc!$B$3,Calc!$B$2)),Calc!$B$11=0),"",IF(N(R12)<=0.005,"",IF(Start!$D$10="Avalanche",INDEX(Calc!W$75:W$89,Calc!$F$11),INDEX(Calc!W$50:W$64,Calc!$D$11)))) | S13: =IF(T13="","",N(T12)*(1+Start!$E$20/12)-T13) | T13: =IF(OR(OR(Calc!$B$4=0,$B13>IF(Start!$D$10="Avalanche",Calc!$B$3,Calc!$B$2)),Calc!$B$12=0),"",IF(N(T12)<=0.005,"",IF(Start!$D$10="Avalanche",INDEX(Calc!W$75:W$89,Calc!$F$12),INDEX(Calc!W$50:W$64,Calc!$D$12)))) | U13: =IF(V13="","",N(V12)*(1+Start!$E$21/12)-V13) | V13: =IF(OR(OR(Calc!$B$4=0,$B13>IF(Start!$D$10="Avalanche",Calc!$B$3,Calc!$B$2)),Calc!$B$13=0),"",IF(N(V12)<=0.005,"",IF(Start!$D$10="Avalanche",INDEX(Calc!W$75:W$89,Calc!$F$13),INDEX(Calc!W$50:W$64,Calc!$D$13)))) | W13: =IF(X13="","",N(X12)*(1+Start!$E$22/12)-X13) | X13: =IF(OR(OR(Calc!$B$4=0,$B13>IF(Start!$D$10="Avalanche",Calc!$B$3,Calc!$B$2)),Calc!$B$14=0),"",IF(N(X12)<=0.005,"",IF(Start!$D$10="Avalanche",INDEX(Calc!W$75:W$89,Calc!$F$14),INDEX(Calc!W$50:W$64,Calc!$D$14)))) | Y13: =IF(Z13="","",N(Z12)*(1+Start!$E$23/12)-Z13) | Z13: =IF(OR(OR(Calc!$B$4=0,$B13>IF(Start!$D$10="Avalanche",Calc!$B$3,Calc!$B$2)),Calc!$B$15=0),"",IF(N(Z12)<=0.005,"",IF(Start!$D$10="Avalanche",INDEX(Calc!W$75:W$89,Calc!$F$15),INDEX(Calc!W$50:W$64,Calc!$D$15)))) | AA13: =IF(AB13="","",N(AB12)*(1+Start!$E$24/12)-AB13) | AB13: =IF(OR(OR(Calc!$B$4=0,$B13>IF(Start!$D$10="Avalanche",Calc!$B$3,Calc!$B$2)),Calc!$B$16=0),"",IF(N(AB12)<=0.005,"",IF(Start!$D$10="Avalanche",INDEX(Calc!W$75:W$89,Calc!$F$16),INDEX(Calc!W$50:W$64,Calc!$D$16)))) | AC13: =IF(AD13="","",N(AD12)*(1+Start!$E$25/12)-AD13) | AD13: =IF(OR(OR(Calc!$B$4=0,$B13>IF(Start!$D$10="Avalanche",Calc!$B$3,Calc!$B$2)),Calc!$B$17=0),"",IF(N(AD12)<=0.005,"",IF(Start!$D$10="Avalanche",INDEX(Calc!W$75:W$89,Calc!$F$17),INDEX(Calc!W$50:W$64,Calc!$D$17)))) | AE13: =IF(AF13="","",N(AF12)*(1+Start!$E$26/12)-AF13) | AF13: =IF(OR(OR(Calc!$B$4=0,$B13>IF(Start!$D$10="Avalanche",Calc!$B$3,Calc!$B$2)),Calc!$B$18=0),"",IF(N(AF12)<=0.005,"",IF(Start!$D$10="Avalanche",INDEX(Calc!W$75:W$89,Calc!$F$18),INDEX(Calc!W$50:W$64,Calc!$D$18)))) | AG13: =IF(AH13="","",N(AH12)*(1+Start!$E$27/12)-AH13) | AH13: =IF(OR(OR(Calc!$B$4=0,$B13>IF(Start!$D$10="Avalanche",Calc!$B$3,Calc!$B$2)),Calc!$B$19=0),"",IF(N(AH12)<=0.005,"",IF(Start!$D$10="Avalanche",INDEX(Calc!W$75:W$89,Calc!$F$19),INDEX(Calc!W$50:W$64,Calc!$D$19)))) | AI13: =IF(AJ13="","",N(AJ12)*(1+Start!$E$28/12)-AJ13) | AJ13: =IF(OR(OR(Calc!$B$4=0,$B13>IF(Start!$D$10="Avalanche",Calc!$B$3,Calc!$B$2)),Calc!$B$20=0),"",IF(N(AJ12)<=0.005,"",IF(Start!$D$10="Avalanche",INDEX(Calc!W$75:W$89,Calc!$F$20),INDEX(Calc!W$50:W$64,Calc!$D$20))))
B14: 8 | C14: =IF(Calc!$B$4=0,"",EDATE(Start!$D$11,7)) | D14: =IF(OR(Calc!$B$4=0,$B14>IF(Start!$D$10="Avalanche",Calc!$B$3,Calc!$B$2)),"",SUM(G14,I14,K14,M14,O14,Q14,S14,U14,W14,Y14,AA14,AC14,AE14,AG14,AI14)) | E14: =IF(OR(Calc!$B$4=0,$B14>IF(Start!$D$10="Avalanche",Calc!$B$3,Calc!$B$2)),"",IF(Start!$D$10="Avalanche",Calc!X$72,Calc!X$47)) | F14: =IF(Calc!$B$4=0,"",IF($B14>IF(Start!$D$10="Avalanche",Calc!$B$3,Calc!$B$2),NA(),SUM(H14,J14,L14,N14,P14,R14,T14,V14,X14,Z14,AB14,AD14,AF14,AH14,AJ14))) | G14: =IF(H14="","",N(H13)*(1+Start!$E$14/12)-H14) | H14: =IF(OR(OR(Calc!$B$4=0,$B14>IF(Start!$D$10="Avalanche",Calc!$B$3,Calc!$B$2)),Calc!$B$6=0),"",IF(N(H13)<=0.005,"",IF(Start!$D$10="Avalanche",INDEX(Calc!Z$75:Z$89,Calc!$F$6),INDEX(Calc!Z$50:Z$64,Calc!$D$6)))) | I14: =IF(J14="","",N(J13)*(1+Start!$E$15/12)-J14) | J14: =IF(OR(OR(Calc!$B$4=0,$B14>IF(Start!$D$10="Avalanche",Calc!$B$3,Calc!$B$2)),Calc!$B$7=0),"",IF(N(J13)<=0.005,"",IF(Start!$D$10="Avalanche",INDEX(Calc!Z$75:Z$89,Calc!$F$7),INDEX(Calc!Z$50:Z$64,Calc!$D$7)))) | K14: =IF(L14="","",N(L13)*(1+Start!$E$16/12)-L14) | L14: =IF(OR(OR(Calc!$B$4=0,$B14>IF(Start!$D$10="Avalanche",Calc!$B$3,Calc!$B$2)),Calc!$B$8=0),"",IF(N(L13)<=0.005,"",IF(Start!$D$10="Avalanche",INDEX(Calc!Z$75:Z$89,Calc!$F$8),INDEX(Calc!Z$50:Z$64,Calc!$D$8)))) | M14: =IF(N14="","",N(N13)*(1+Start!$E$17/12)-N14) | N14: =IF(OR(OR(Calc!$B$4=0,$B14>IF(Start!$D$10="Avalanche",Calc!$B$3,Calc!$B$2)),Calc!$B$9=0),"",IF(N(N13)<=0.005,"",IF(Start!$D$10="Avalanche",INDEX(Calc!Z$75:Z$89,Calc!$F$9),INDEX(Calc!Z$50:Z$64,Calc!$D$9)))) | O14: =IF(P14="","",N(P13)*(1+Start!$E$18/12)-P14) | P14: =IF(OR(OR(Calc!$B$4=0,$B14>IF(Start!$D$10="Avalanche",Calc!$B$3,Calc!$B$2)),Calc!$B$10=0),"",IF(N(P13)<=0.005,"",IF(Start!$D$10="Avalanche",INDEX(Calc!Z$75:Z$89,Calc!$F$10),INDEX(Calc!Z$50:Z$64,Calc!$D$10)))) | Q14: =IF(R14="","",N(R13)*(1+Start!$E$19/12)-R14) | R14: =IF(OR(OR(Calc!$B$4=0,$B14>IF(Start!$D$10="Avalanche",Calc!$B$3,Calc!$B$2)),Calc!$B$11=0),"",IF(N(R13)<=0.005,"",IF(Start!$D$10="Avalanche",INDEX(Calc!Z$75:Z$89,Calc!$F$11),INDEX(Calc!Z$50:Z$64,Calc!$D$11)))) | S14: =IF(T14="","",N(T13)*(1+Start!$E$20/12)-T14) | T14: =IF(OR(OR(Calc!$B$4=0,$B14>IF(Start!$D$10="Avalanche",Calc!$B$3,Calc!$B$2)),Calc!$B$12=0),"",IF(N(T13)<=0.005,"",IF(Start!$D$10="Avalanche",INDEX(Calc!Z$75:Z$89,Calc!$F$12),INDEX(Calc!Z$50:Z$64,Calc!$D$12)))) | U14: =IF(V14="","",N(V13)*(1+Start!$E$21/12)-V14) | V14: =IF(OR(OR(Calc!$B$4=0,$B14>IF(Start!$D$10="Avalanche",Calc!$B$3,Calc!$B$2)),Calc!$B$13=0),"",IF(N(V13)<=0.005,"",IF(Start!$D$10="Avalanche",INDEX(Calc!Z$75:Z$89,Calc!$F$13),INDEX(Calc!Z$50:Z$64,Calc!$D$13)))) | W14: =IF(X14="","",N(X13)*(1+Start!$E$22/12)-X14) | X14: =IF(OR(OR(Calc!$B$4=0,$B14>IF(Start!$D$10="Avalanche",Calc!$B$3,Calc!$B$2)),Calc!$B$14=0),"",IF(N(X13)<=0.005,"",IF(Start!$D$10="Avalanche",INDEX(Calc!Z$75:Z$89,Calc!$F$14),INDEX(Calc!Z$50:Z$64,Calc!$D$14)))) | Y14: =IF(Z14="","",N(Z13)*(1+Start!$E$23/12)-Z14) | Z14: =IF(OR(OR(Calc!$B$4=0,$B14>IF(Start!$D$10="Avalanche",Calc!$B$3,Calc!$B$2)),Calc!$B$15=0),"",IF(N(Z13)<=0.005,"",IF(Start!$D$10="Avalanche",INDEX(Calc!Z$75:Z$89,Calc!$F$15),INDEX(Calc!Z$50:Z$64,Calc!$D$15)))) | AA14: =IF(AB14="","",N(AB13)*(1+Start!$E$24/12)-AB14) | AB14: =IF(OR(OR(Calc!$B$4=0,$B14>IF(Start!$D$10="Avalanche",Calc!$B$3,Calc!$B$2)),Calc!$B$16=0),"",IF(N(AB13)<=0.005,"",IF(Start!$D$10="Avalanche",INDEX(Calc!Z$75:Z$89,Calc!$F$16),INDEX(Calc!Z$50:Z$64,Calc!$D$16)))) | AC14: =IF(AD14="","",N(AD13)*(1+Start!$E$25/12)-AD14) | AD14: =IF(OR(OR(Calc!$B$4=0,$B14>IF(Start!$D$10="Avalanche",Calc!$B$3,Calc!$B$2)),Calc!$B$17=0),"",IF(N(AD13)<=0.005,"",IF(Start!$D$10="Avalanche",INDEX(Calc!Z$75:Z$89,Calc!$F$17),INDEX(Calc!Z$50:Z$64,Calc!$D$17)))) | AE14: =IF(AF14="","",N(AF13)*(1+Start!$E$26/12)-AF14) | AF14: =IF(OR(OR(Calc!$B$4=0,$B14>IF(Start!$D$10="Avalanche",Calc!$B$3,Calc!$B$2)),Calc!$B$18=0),"",IF(N(AF13)<=0.005,"",IF(Start!$D$10="Avalanche",INDEX(Calc!Z$75:Z$89,Calc!$F$18),INDEX(Calc!Z$50:Z$64,Calc!$D$18)))) | AG14: =IF(AH14="","",N(AH13)*(1+Start!$E$27/12)-AH14) | AH14: =IF(OR(OR(Calc!$B$4=0,$B14>IF(Start!$D$10="Avalanche",Calc!$B$3,Calc!$B$2)),Calc!$B$19=0),"",IF(N(AH13)<=0.005,"",IF(Start!$D$10="Avalanche",INDEX(Calc!Z$75:Z$89,Calc!$F$19),INDEX(Calc!Z$50:Z$64,Calc!$D$19)))) | AI14: =IF(AJ14="","",N(AJ13)*(1+Start!$E$28/12)-AJ14) | AJ14: =IF(OR(OR(Calc!$B$4=0,$B14>IF(Start!$D$10="Avalanche",Calc!$B$3,Calc!$B$2)),Calc!$B$20=0),"",IF(N(AJ13)<=0.005,"",IF(Start!$D$10="Avalanche",INDEX(Calc!Z$75:Z$89,Calc!$F$20),INDEX(Calc!Z$50:Z$64,Calc!$D$20))))
B15: 9 | C15: =IF(Calc!$B$4=0,"",EDATE(Start!$D$11,8)) | D15: =IF(OR(Calc!$B$4=0,$B15>IF(Start!$D$10="Avalanche",Calc!$B$3,Calc!$B$2)),"",SUM(G15,I15,K15,M15,O15,Q15,S15,U15,W15,Y15,AA15,AC15,AE15,AG15,AI15)) | E15: =IF(OR(Calc!$B$4=0,$B15>IF(Start!$D$10="Avalanche",Calc!$B$3,Calc!$B$2)),"",IF(Start!$D$10="Avalanche",Calc!AA$72,Calc!AA$47)) | F15: =IF(Calc!$B$4=0,"",IF($B15>IF(Start!$D$10="Avalanche",Calc!$B$3,Calc!$B$2),NA(),SUM(H15,J15,L15,N15,P15,R15,T15,V15,X15,Z15,AB15,AD15,AF15,AH15,AJ15))) | G15: =IF(H15="","",N(H14)*(1+Start!$E$14/12)-H15) | H15: =IF(OR(OR(Calc!$B$4=0,$B15>IF(Start!$D$10="Avalanche",Calc!$B$3,Calc!$B$2)),Calc!$B$6=0),"",IF(N(H14)<=0.005,"",IF(Start!$D$10="Avalanche",INDEX(Calc!AC$75:AC$89,Calc!$F$6),INDEX(Calc!AC$50:AC$64,Calc!$D$6)))) | I15: =IF(J15="","",N(J14)*(1+Start!$E$15/12)-J15) | J15: =IF(OR(OR(Calc!$B$4=0,$B15>IF(Start!$D$10="Avalanche",Calc!$B$3,Calc!$B$2)),Calc!$B$7=0),"",IF(N(J14)<=0.005,"",IF(Start!$D$10="Avalanche",INDEX(Calc!AC$75:AC$89,Calc!$F$7),INDEX(Calc!AC$50:AC$64,Calc!$D$7)))) | K15: =IF(L15="","",N(L14)*(1+Start!$E$16/12)-L15) | L15: =IF(OR(OR(Calc!$B$4=0,$B15>IF(Start!$D$10="Avalanche",Calc!$B$3,Calc!$B$2)),Calc!$B$8=0),"",IF(N(L14)<=0.005,"",IF(Start!$D$10="Avalanche",INDEX(Calc!AC$75:AC$89,Calc!$F$8),INDEX(Calc!AC$50:AC$64,Calc!$D$8)))) | M15: =IF(N15="","",N(N14)*(1+Start!$E$17/12)-N15) | N15: =IF(OR(OR(Calc!$B$4=0,$B15>IF(Start!$D$10="Avalanche",Calc!$B$3,Calc!$B$2)),Calc!$B$9=0),"",IF(N(N14)<=0.005,"",IF(Start!$D$10="Avalanche",INDEX(Calc!AC$75:AC$89,Calc!$F$9),INDEX(Calc!AC$50:AC$64,Calc!$D$9)))) | O15: =IF(P15="","",N(P14)*(1+Start!$E$18/12)-P15) | P15: =IF(OR(OR(Calc!$B$4=0,$B15>IF(Start!$D$10="Avalanche",Calc!$B$3,Calc!$B$2)),Calc!$B$10=0),"",IF(N(P14)<=0.005,"",IF(Start!$D$10="Avalanche",INDEX(Calc!AC$75:AC$89,Calc!$F$10),INDEX(Calc!AC$50:AC$64,Calc!$D$10)))) | Q15: =IF(R15="","",N(R14)*(1+Start!$E$19/12)-R15) | R15: =IF(OR(OR(Calc!$B$4=0,$B15>IF(Start!$D$10="Avalanche",Calc!$B$3,Calc!$B$2)),Calc!$B$11=0),"",IF(N(R14)<=0.005,"",IF(Start!$D$10="Avalanche",INDEX(Calc!AC$75:AC$89,Calc!$F$11),INDEX(Calc!AC$50:AC$64,Calc!$D$11)))) | S15: =IF(T15="","",N(T14)*(1+Start!$E$20/12)-T15) | T15: =IF(OR(OR(Calc!$B$4=0,$B15>IF(Start!$D$10="Avalanche",Calc!$B$3,Calc!$B$2)),Calc!$B$12=0),"",IF(N(T14)<=0.005,"",IF(Start!$D$10="Avalanche",INDEX(Calc!AC$75:AC$89,Calc!$F$12),INDEX(Calc!AC$50:AC$64,Calc!$D$12)))) | U15: =IF(V15="","",N(V14)*(1+Start!$E$21/12)-V15) | V15: =IF(OR(OR(Calc!$B$4=0,$B15>IF(Start!$D$10="Avalanche",Calc!$B$3,Calc!$B$2)),Calc!$B$13=0),"",IF(N(V14)<=0.005,"",IF(Start!$D$10="Avalanche",INDEX(Calc!AC$75:AC$89,Calc!$F$13),INDEX(Calc!AC$50:AC$64,Calc!$D$13)))) | W15: =IF(X15="","",N(X14)*(1+Start!$E$22/12)-X15) | X15: =IF(OR(OR(Calc!$B$4=0,$B15>IF(Start!$D$10="Avalanche",Calc!$B$3,Calc!$B$2)),Calc!$B$14=0),"",IF(N(X14)<=0.005,"",IF(Start!$D$10="Avalanche",INDEX(Calc!AC$75:AC$89,Calc!$F$14),INDEX(Calc!AC$50:AC$64,Calc!$D$14)))) | Y15: =IF(Z15="","",N(Z14)*(1+Start!$E$23/12)-Z15) | Z15: =IF(OR(OR(Calc!$B$4=0,$B15>IF(Start!$D$10="Avalanche",Calc!$B$3,Calc!$B$2)),Calc!$B$15=0),"",IF(N(Z14)<=0.005,"",IF(Start!$D$10="Avalanche",INDEX(Calc!AC$75:AC$89,Calc!$F$15),INDEX(Calc!AC$50:AC$64,Calc!$D$15)))) | AA15: =IF(AB15="","",N(AB14)*(1+Start!$E$24/12)-AB15) | AB15: =IF(OR(OR(Calc!$B$4=0,$B15>IF(Start!$D$10="Avalanche",Calc!$B$3,Calc!$B$2)),Calc!$B$16=0),"",IF(N(AB14)<=0.005,"",IF(Start!$D$10="Avalanche",INDEX(Calc!AC$75:AC$89,Calc!$F$16),INDEX(Calc!AC$50:AC$64,Calc!$D$16)))) | AC15: =IF(AD15="","",N(AD14)*(1+Start!$E$25/12)-AD15) | AD15: =IF(OR(OR(Calc!$B$4=0,$B15>IF(Start!$D$10="Avalanche",Calc!$B$3,Calc!$B$2)),Calc!$B$17=0),"",IF(N(AD14)<=0.005,"",IF(Start!$D$10="Avalanche",INDEX(Calc!AC$75:AC$89,Calc!$F$17),INDEX(Calc!AC$50:AC$64,Calc!$D$17)))) | AE15: =IF(AF15="","",N(AF14)*(1+Start!$E$26/12)-AF15) | AF15: =IF(OR(OR(Calc!$B$4=0,$B15>IF(Start!$D$10="Avalanche",Calc!$B$3,Calc!$B$2)),Calc!$B$18=0),"",IF(N(AF14)<=0.005,"",IF(Start!$D$10="Avalanche",INDEX(Calc!AC$75:AC$89,Calc!$F$18),INDEX(Calc!AC$50:AC$64,Calc!$D$18)))) | AG15: =IF(AH15="","",N(AH14)*(1+Start!$E$27/12)-AH15) | AH15: =IF(OR(OR(Calc!$B$4=0,$B15>IF(Start!$D$10="Avalanche",Calc!$B$3,Calc!$B$2)),Calc!$B$19=0),"",IF(N(AH14)<=0.005,"",IF(Start!$D$10="Avalanche",INDEX(Calc!AC$75:AC$89,Calc!$F$19),INDEX(Calc!AC$50:AC$64,Calc!$D$19)))) | AI15: =IF(AJ15="","",N(AJ14)*(1+Start!$E$28/12)-AJ15) | AJ15: =IF(OR(OR(Calc!$B$4=0,$B15>IF(Start!$D$10="Avalanche",Calc!$B$3,Calc!$B$2)),Calc!$B$20=0),"",IF(N(AJ14)<=0.005,"",IF(Start!$D$10="Avalanche",INDEX(Calc!AC$75:AC$89,Calc!$F$20),INDEX(Calc!AC$50:AC$64,Calc!$D$20))))
B16: 10 | C16: =IF(Calc!$B$4=0,"",EDATE(Start!$D$11,9)) | D16: =IF(OR(Calc!$B$4=0,$B16>IF(Start!$D$10="Avalanche",Calc!$B$3,Calc!$B$2)),"",SUM(G16,I16,K16,M16,O16,Q16,S16,U16,W16,Y16,AA16,AC16,AE16,AG16,AI16)) | E16: =IF(OR(Calc!$B$4=0,$B16>IF(Start!$D$10="Avalanche",Calc!$B$3,Calc!$B$2)),"",IF(Start!$D$10="Avalanche",Calc!AD$72,Calc!AD$47)) | F16: =IF(Calc!$B$4=0,"",IF($B16>IF(Start!$D$10="Avalanche",Calc!$B$3,Calc!$B$2),NA(),SUM(H16,J16,L16,N16,P16,R16,T16,V16,X16,Z16,AB16,AD16,AF16,AH16,AJ16))) | G16: =IF(H16="","",N(H15)*(1+Start!$E$14/12)-H16) | H16: =IF(OR(OR(Calc!$B$4=0,$B16>IF(Start!$D$10="Avalanche",Calc!$B$3,Calc!$B$2)),Calc!$B$6=0),"",IF(N(H15)<=0.005,"",IF(Start!$D$10="Avalanche",INDEX(Calc!AF$75:AF$89,Calc!$F$6),INDEX(Calc!AF$50:AF$64,Calc!$D$6)))) | I16: =IF(J16="","",N(J15)*(1+Start!$E$15/12)-J16) | J16: =IF(OR(OR(Calc!$B$4=0,$B16>IF(Start!$D$10="Avalanche",Calc!$B$3,Calc!$B$2)),Calc!$B$7=0),"",IF(N(J15)<=0.005,"",IF(Start!$D$10="Avalanche",INDEX(Calc!AF$75:AF$89,Calc!$F$7),INDEX(Calc!AF$50:AF$64,Calc!$D$7)))) | K16: =IF(L16="","",N(L15)*(1+Start!$E$16/12)-L16) | L16: =IF(OR(OR(Calc!$B$4=0,$B16>IF(Start!$D$10="Avalanche",Calc!$B$3,Calc!$B$2)),Calc!$B$8=0),"",IF(N(L15)<=0.005,"",IF(Start!$D$10="Avalanche",INDEX(Calc!AF$75:AF$89,Calc!$F$8),INDEX(Calc!AF$50:AF$64,Calc!$D$8)))) | M16: =IF(N16="","",N(N15)*(1+Start!$E$17/12)-N16) | N16: =IF(OR(OR(Calc!$B$4=0,$B16>IF(Start!$D$10="Avalanche",Calc!$B$3,Calc!$B$2)),Calc!$B$9=0),"",IF(N(N15)<=0.005,"",IF(Start!$D$10="Avalanche",INDEX(Calc!AF$75:AF$89,Calc!$F$9),INDEX(Calc!AF$50:AF$64,Calc!$D$9)))) | O16: =IF(P16="","",N(P15)*(1+Start!$E$18/12)-P16) | P16: =IF(OR(OR(Calc!$B$4=0,$B16>IF(Start!$D$10="Avalanche",Calc!$B$3,Calc!$B$2)),Calc!$B$10=0),"",IF(N(P15)<=0.005,"",IF(Start!$D$10="Avalanche",INDEX(Calc!AF$75:AF$89,Calc!$F$10),INDEX(Calc!AF$50:AF$64,Calc!$D$10)))) | Q16: =IF(R16="","",N(R15)*(1+Start!$E$19/12)-R16) | R16: =IF(OR(OR(Calc!$B$4=0,$B16>IF(Start!$D$10="Avalanche",Calc!$B$3,Calc!$B$2)),Calc!$B$11=0),"",IF(N(R15)<=0.005,"",IF(Start!$D$10="Avalanche",INDEX(Calc!AF$75:AF$89,Calc!$F$11),INDEX(Calc!AF$50:AF$64,Calc!$D$11)))) | S16: =IF(T16="","",N(T15)*(1+Start!$E$20/12)-T16) | T16: =IF(OR(OR(Calc!$B$4=0,$B16>IF(Start!$D$10="Avalanche",Calc!$B$3,Calc!$B$2)),Calc!$B$12=0),"",IF(N(T15)<=0.005,"",IF(Start!$D$10="Avalanche",INDEX(Calc!AF$75:AF$89,Calc!$F$12),INDEX(Calc!AF$50:AF$64,Calc!$D$12)))) | U16: =IF(V16="","",N(V15)*(1+Start!$E$21/12)-V16) | V16: =IF(OR(OR(Calc!$B$4=0,$B16>IF(Start!$D$10="Avalanche",Calc!$B$3,Calc!$B$2)),Calc!$B$13=0),"",IF(N(V15)<=0.005,"",IF(Start!$D$10="Avalanche",INDEX(Calc!AF$75:AF$89,Calc!$F$13),INDEX(Calc!AF$50:AF$64,Calc!$D$13)))) | W16: =IF(X16="","",N(X15)*(1+Start!$E$22/12)-X16) | X16: =IF(OR(OR(Calc!$B$4=0,$B16>IF(Start!$D$10="Avalanche",Calc!$B$3,Calc!$B$2)),Calc!$B$14=0),"",IF(N(X15)<=0.005,"",IF(Start!$D$10="Avalanche",INDEX(Calc!AF$75:AF$89,Calc!$F$14),INDEX(Calc!AF$50:AF$64,Calc!$D$14)))) | Y16: =IF(Z16="","",N(Z15)*(1+Start!$E$23/12)-Z16) | Z16: =IF(OR(OR(Calc!$B$4=0,$B16>IF(Start!$D$10="Avalanche",Calc!$B$3,Calc!$B$2)),Calc!$B$15=0),"",IF(N(Z15)<=0.005,"",IF(Start!$D$10="Avalanche",INDEX(Calc!AF$75:AF$89,Calc!$F$15),INDEX(Calc!AF$50:AF$64,Calc!$D$15)))) | AA16: =IF(AB16="","",N(AB15)*(1+Start!$E$24/12)-AB16) | AB16: =IF(OR(OR(Calc!$B$4=0,$B16>IF(Start!$D$10="Avalanche",Calc!$B$3,Calc!$B$2)),Calc!$B$16=0),"",IF(N(AB15)<=0.005,"",IF(Start!$D$10="Avalanche",INDEX(Calc!AF$75:AF$89,Calc!$F$16),INDEX(Calc!AF$50:AF$64,Calc!$D$16)))) | AC16: =IF(AD16="","",N(AD15)*(1+Start!$E$25/12)-AD16) | AD16: =IF(OR(OR(Calc!$B$4=0,$B16>IF(Start!$D$10="Avalanche",Calc!$B$3,Calc!$B$2)),Calc!$B$17=0),"",IF(N(AD15)<=0.005,"",IF(Start!$D$10="Avalanche",INDEX(Calc!AF$75:AF$89,Calc!$F$17),INDEX(Calc!AF$50:AF$64,Calc!$D$17)))) | AE16: =IF(AF16="","",N(AF15)*(1+Start!$E$26/12)-AF16) | AF16: =IF(OR(OR(Calc!$B$4=0,$B16>IF(Start!$D$10="Avalanche",Calc!$B$3,Calc!$B$2)),Calc!$B$18=0),"",IF(N(AF15)<=0.005,"",IF(Start!$D$10="Avalanche",INDEX(Calc!AF$75:AF$89,Calc!$F$18),INDEX(Calc!AF$50:AF$64,Calc!$D$18)))) | AG16: =IF(AH16="","",N(AH15)*(1+Start!$E$27/12)-AH16) | AH16: =IF(OR(OR(Calc!$B$4=0,$B16>IF(Start!$D$10="Avalanche",Calc!$B$3,Calc!$B$2)),Calc!$B$19=0),"",IF(N(AH15)<=0.005,"",IF(Start!$D$10="Avalanche",INDEX(Calc!AF$75:AF$89,Calc!$F$19),INDEX(Calc!AF$50:AF$64,Calc!$D$19)))) | AI16: =IF(AJ16="","",N(AJ15)*(1+Start!$E$28/12)-AJ16) | AJ16: =IF(OR(OR(Calc!$B$4=0,$B16>IF(Start!$D$10="Avalanche",Calc!$B$3,Calc!$B$2)),Calc!$B$20=0),"",IF(N(AJ15)<=0.005,"",IF(Start!$D$10="Avalanche",INDEX(Calc!AF$75:AF$89,Calc!$F$20),INDEX(Calc!AF$50:AF$64,Calc!$D$20))))
B17: 11 | C17: =IF(Calc!$B$4=0,"",EDATE(Start!$D$11,10)) | D17: =IF(OR(Calc!$B$4=0,$B17>IF(Start!$D$10="Avalanche",Calc!$B$3,Calc!$B$2)),"",SUM(G17,I17,K17,M17,O17,Q17,S17,U17,W17,Y17,AA17,AC17,AE17,AG17,AI17)) | E17: =IF(OR(Calc!$B$4=0,$B17>IF(Start!$D$10="Avalanche",Calc!$B$3,Calc!$B$2)),"",IF(Start!$D$10="Avalanche",Calc!AG$72,Calc!AG$47)) | F17: =IF(Calc!$B$4=0,"",IF($B17>IF(Start!$D$10="Avalanche",Calc!$B$3,Calc!$B$2),NA(),SUM(H17,J17,L17,N17,P17,R17,T17,V17,X17,Z17,AB17,AD17,AF17,AH17,AJ17))) | G17: =IF(H17="","",N(H16)*(1+Start!$E$14/12)-H17) | H17: =IF(OR(OR(Calc!$B$4=0,$B17>IF(Start!$D$10="Avalanche",Calc!$B$3,Calc!$B$2)),Calc!$B$6=0),"",IF(N(H16)<=0.005,"",IF(Start!$D$10="Avalanche",INDEX(Calc!AI$75:AI$89,Calc!$F$6),INDEX(Calc!AI$50:AI$64,Calc!$D$6)))) | I17: =IF(J17="","",N(J16)*(1+Start!$E$15/12)-J17) | J17: =IF(OR(OR(Calc!$B$4=0,$B17>IF(Start!$D$10="Avalanche",Calc!$B$3,Calc!$B$2)),Calc!$B$7=0),"",IF(N(J16)<=0.005,"",IF(Start!$D$10="Avalanche",INDEX(Calc!AI$75:AI$89,Calc!$F$7),INDEX(Calc!AI$50:AI$64,Calc!$D$7)))) | K17: =IF(L17="","",N(L16)*(1+Start!$E$16/12)-L17) | L17: =IF(OR(OR(Calc!$B$4=0,$B17>IF(Start!$D$10="Avalanche",Calc!$B$3,Calc!$B$2)),Calc!$B$8=0),"",IF(N(L16)<=0.005,"",IF(Start!$D$10="Avalanche",INDEX(Calc!AI$75:AI$89,Calc!$F$8),INDEX(Calc!AI$50:AI$64,Calc!$D$8)))) | M17: =IF(N17="","",N(N16)*(1+Start!$E$17/12)-N17) | N17: =IF(OR(OR(Calc!$B$4=0,$B17>IF(Start!$D$10="Avalanche",Calc!$B$3,Calc!$B$2)),Calc!$B$9=0),"",IF(N(N16)<=0.005,"",IF(Start!$D$10="Avalanche",INDEX(Calc!AI$75:AI$89,Calc!$F$9),INDEX(Calc!AI$50:AI$64,Calc!$D$9)))) | O17: =IF(P17="","",N(P16)*(1+Start!$E$18/12)-P17) | P17: =IF(OR(OR(Calc!$B$4=0,$B17>IF(Start!$D$10="Avalanche",Calc!$B$3,Calc!$B$2)),Calc!$B$10=0),"",IF(N(P16)<=0.005,"",IF(Start!$D$10="Avalanche",INDEX(Calc!AI$75:AI$89,Calc!$F$10),INDEX(Calc!AI$50:AI$64,Calc!$D$10)))) | Q17: =IF(R17="","",N(R16)*(1+Start!$E$19/12)-R17) | R17: =IF(OR(OR(Calc!$B$4=0,$B17>IF(Start!$D$10="Avalanche",Calc!$B$3,Calc!$B$2)),Calc!$B$11=0),"",IF(N(R16)<=0.005,"",IF(Start!$D$10="Avalanche",INDEX(Calc!AI$75:AI$89,Calc!$F$11),INDEX(Calc!AI$50:AI$64,Calc!$D$11)))) | S17: =IF(T17="","",N(T16)*(1+Start!$E$20/12)-T17) | T17: =IF(OR(OR(Calc!$B$4=0,$B17>IF(Start!$D$10="Avalanche",Calc!$B$3,Calc!$B$2)),Calc!$B$12=0),"",IF(N(T16)<=0.005,"",IF(Start!$D$10="Avalanche",INDEX(Calc!AI$75:AI$89,Calc!$F$12),INDEX(Calc!AI$50:AI$64,Calc!$D$12)))) | U17: =IF(V17="","",N(V16)*(1+Start!$E$21/12)-V17) | V17: =IF(OR(OR(Calc!$B$4=0,$B17>IF(Start!$D$10="Avalanche",Calc!$B$3,Calc!$B$2)),Calc!$B$13=0),"",IF(N(V16)<=0.005,"",IF(Start!$D$10="Avalanche",INDEX(Calc!AI$75:AI$89,Calc!$F$13),INDEX(Calc!AI$50:AI$64,Calc!$D$13)))) | W17: =IF(X17="","",N(X16)*(1+Start!$E$22/12)-X17) | X17: =IF(OR(OR(Calc!$B$4=0,$B17>IF(Start!$D$10="Avalanche",Calc!$B$3,Calc!$B$2)),Calc!$B$14=0),"",IF(N(X16)<=0.005,"",IF(Start!$D$10="Avalanche",INDEX(Calc!AI$75:AI$89,Calc!$F$14),INDEX(Calc!AI$50:AI$64,Calc!$D$14)))) | Y17: =IF(Z17="","",N(Z16)*(1+Start!$E$23/12)-Z17) | Z17: =IF(OR(OR(Calc!$B$4=0,$B17>IF(Start!$D$10="Avalanche",Calc!$B$3,Calc!$B$2)),Calc!$B$15=0),"",IF(N(Z16)<=0.005,"",IF(Start!$D$10="Avalanche",INDEX(Calc!AI$75:AI$89,Calc!$F$15),INDEX(Calc!AI$50:AI$64,Calc!$D$15)))) | AA17: =IF(AB17="","",N(AB16)*(1+Start!$E$24/12)-AB17) | AB17: =IF(OR(OR(Calc!$B$4=0,$B17>IF(Start!$D$10="Avalanche",Calc!$B$3,Calc!$B$2)),Calc!$B$16=0),"",IF(N(AB16)<=0.005,"",IF(Start!$D$10="Avalanche",INDEX(Calc!AI$75:AI$89,Calc!$F$16),INDEX(Calc!AI$50:AI$64,Calc!$D$16)))) | AC17: =IF(AD17="","",N(AD16)*(1+Start!$E$25/12)-AD17) | AD17: =IF(OR(OR(Calc!$B$4=0,$B17>IF(Start!$D$10="Avalanche",Calc!$B$3,Calc!$B$2)),Calc!$B$17=0),"",IF(N(AD16)<=0.005,"",IF(Start!$D$10="Avalanche",INDEX(Calc!AI$75:AI$89,Calc!$F$17),INDEX(Calc!AI$50:AI$64,Calc!$D$17)))) | AE17: =IF(AF17="","",N(AF16)*(1+Start!$E$26/12)-AF17) | AF17: =IF(OR(OR(Calc!$B$4=0,$B17>IF(Start!$D$10="Avalanche",Calc!$B$3,Calc!$B$2)),Calc!$B$18=0),"",IF(N(AF16)<=0.005,"",IF(Start!$D$10="Avalanche",INDEX(Calc!AI$75:AI$89,Calc!$F$18),INDEX(Calc!AI$50:AI$64,Calc!$D$18)))) | AG17: =IF(AH17="","",N(AH16)*(1+Start!$E$27/12)-AH17) | AH17: =IF(OR(OR(Calc!$B$4=0,$B17>IF(Start!$D$10="Avalanche",Calc!$B$3,Calc!$B$2)),Calc!$B$19=0),"",IF(N(AH16)<=0.005,"",IF(Start!$D$10="Avalanche",INDEX(Calc!AI$75:AI$89,Calc!$F$19),INDEX(Calc!AI$50:AI$64,Calc!$D$19)))) | AI17: =IF(AJ17="","",N(AJ16)*(1+Start!$E$28/12)-AJ17) | AJ17: =IF(OR(OR(Calc!$B$4=0,$B17>IF(Start!$D$10="Avalanche",Calc!$B$3,Calc!$B$2)),Calc!$B$20=0),"",IF(N(AJ16)<=0.005,"",IF(Start!$D$10="Avalanche",INDEX(Calc!AI$75:AI$89,Calc!$F$20),INDEX(Calc!AI$50:AI$64,Calc!$D$20))))
